<?xml version="1.0" ?>
<sdf version="1.8">
    <model name='X1' canonical_link='chassis'>
        <pose>0 0 0 0 0 0</pose>

        <link name='chassis'>
            <pose relative_to='__model__'>0.25 0 0.4 0 0 0</pose>
            <inertial> 
                <mass>1.14395</mass>
                <inertia>
                    <ixx>0.126164</ixx>
                    <ixy>0</ixy>
                    <ixz>0</ixz>
                    <iyy>0.416519</iyy>
                    <iyz>0</iyz>
                    <izz>0.481014</izz>
                </inertia>
            </inertial>

            <visual name='visual'>
                <geometry>
                    <box>
                        <size>1.0 0.5 0.25</size> 
                    </box>
                </geometry>
                <material>
                    <ambient>0.0 0.0 1.0 1</ambient>
                    <diffuse>0.0 0.0 1.0 1</diffuse>
                    <specular>0.0 0.0 1.0 1</specular>
                </material>
            </visual>

            <collision name='collision'> 
                <geometry>
                    <box>
                        <size>1.0 0.5 0.25</size>
                    </box>
                </geometry>
            </collision>

            <sensor name="imu_sensor" type="imu">
                <always_on>1</always_on>
                <update_rate>1</update_rate>
                <visualize>true</visualize>
                <topic>imu</topic>
            </sensor>

            <visual name="camera_front_right_visual">
                <pose>0.43 -0.1 0.26 0 0 0</pose>
                <geometry>
                    <box>
                        <size>0.02 0.02 0.02</size>
                    </box>
                </geometry>
            </visual>

            <sensor name="camera_front_right" type="camera">
                <pose relative_to="chassis">0.43 0.1 0.05 0 0 0</pose>
                <always_on>1</always_on>
                <update_rate>20</update_rate>
                <camera name="camera_front_right">
                    <!--<cameraInfoTopicName>camera_info</cameraInfoTopicName>-->
                    <!--<hackBaseline>0.07</hackBaseline>-->
                    <horizontal_fov>1.0472</horizontal_fov>
                    <lens>
                        <intrinsics>
                            <!-- fx = fy = width / ( 2 * tan (hfov / 2 ) ) -->
                            <fx>1108.5</fx>
                            <fy>1108.5</fy>
                            <!-- cx = ( width + 1 ) / 2 -->
                            <cx>640.5</cx>
                            <!-- cy = ( height + 1 ) / 2 -->
                            <cy>480.5</cy>
                            <s>0</s>
                        </intrinsics>
                    </lens>

                    <distortion>
                        <k1>0.0</k1>
                        <k2>0.0</k2>
                        <k3>0.0</k3>
                        <p1>0.0</p1>
                        <p2>0.0</p2>
                        <center>0.5 0.5</center>
                    </distortion>

                    <image>
                        <width>1280</width>
                        <height>960</height>
                        <format>R8G8B8</format>
                    </image>

                    <clip>
                        <near>0.01</near>
                        <far>300</far>
                    </clip>

                    <noise>
                        <type>gaussian</type>
                        <mean>0</mean>
                        <stddev>0.007</stddev>
                    </noise>
                </camera>
            </sensor>

            <visual name="camera_front_left_visual">
                <pose>0.43 0.1 0.26 0 0 0</pose>
                <geometry>
                    <box>
                        <size>0.02 0.02 0.02</size>
                    </box>
                </geometry>
            </visual>

            <sensor name="camera_front_left" type="camera">
                <pose relative_to="chassis">0.43 -0.1 0.05 0 0 0</pose>
                <always_on>1</always_on>
                <update_rate>20</update_rate>
                <camera name="camera_front_left">
                    <!--<cameraInfoTopicName>camera_info</cameraInfoTopicName>-->
                    <!--<hackBaseline>0.07</hackBaseline>-->
                    <horizontal_fov>1.0472</horizontal_fov>
                    <lens>
                        <intrinsics>
                            <!-- fx = fy = width / ( 2 * tan (hfov / 2 ) ) -->
                            <fx>1108.5</fx>
                            <fy>1108.5</fy>
                            <!-- cx = ( width + 1 ) / 2 -->
                            <cx>640.5</cx>
                            <!-- cy = ( height + 1 ) / 2 -->
                            <cy>480.5</cy>
                            <s>0</s>
                        </intrinsics>
                    </lens>

                    <distortion>
                        <k1>0.0</k1>
                        <k2>0.0</k2>
                        <k3>0.0</k3>
                        <p1>0.0</p1>
                        <p2>0.0</p2>
                        <center>0.5 0.5</center>
                    </distortion>

                    <image>
                        <width>1280</width>
                        <height>960</height>
                        <format>R8G8B8</format>
                    </image>

                    <clip>
                        <near>0.01</near>
                        <far>300</far>
                    </clip>

                    <noise>
                        <type>gaussian</type>
                        <mean>0</mean>
                        <stddev>0.007</stddev>
                    </noise>
                </camera>
            </sensor>

            <sensor name='gpu_lidar' type='gpu_lidar'>"
                <pose relative_to='chassis'>0.4 0 0.25 0 0 0</pose>
                <topic>lidar</topic>
                <update_rate>10</update_rate>
                <ray>
                    <scan>
                        <horizontal>
                        <samples>640</samples>
                        <resolution>1</resolution>
                        <min_angle>-1.396263</min_angle>
                        <max_angle>1.396263</max_angle>
                        </horizontal>
                        <vertical>
                        <samples>1</samples>
                        <resolution>0.01</resolution>
                        <min_angle>0</min_angle>
                        <max_angle>0</max_angle>
                        </vertical>
                    </scan>
                <range>
                    <min>0.08</min>
                    <max>50.0</max>
                    <resolution>0.01</resolution>
                </range>
                </ray>
                <always_on>1</always_on>
                <visualize>true</visualize>
            </sensor>
        </link>

        <!--let's build the left wheel-->
        <link name='left_wheel'>
            <pose relative_to="chassis">-0.25 0.3 0 -1.5707 0 0</pose> <!--angles are in radian-->
            <inertial>
                <mass>2</mass>
                <inertia>
                    <ixx>0.145833</ixx>
                    <ixy>0</ixy>
                    <ixz>0</ixz>
                    <iyy>0.145833</iyy>
                    <iyz>0</iyz>
                    <izz>0.125</izz>
                </inertia>
            </inertial>
            <visual name='visual'>
                <geometry>
                    <cylinder>
                        <radius>0.3</radius>
                        <length>0.1</length>
                    </cylinder>
                </geometry>
                <material>
                    <ambient>0.0 0.0 0.75 1</ambient>
                    <diffuse>0.0 0.0 0.75 1</diffuse>
                    <specular>0.0 0.0 0.75 1</specular>
                </material>
            </visual>
            <collision name='collision'>
                <geometry>
                    <cylinder>
                        <radius>0.3</radius>
                        <length>0.1</length>
                    </cylinder>
                </geometry>
            </collision>
        </link>

        <!--copy and paste for right wheel but change position-->
        <link name='right_wheel'>
            <pose relative_to="chassis">-0.25 -0.3 0 -1.5707 0 0</pose> <!--angles are in radian-->
            <inertial>
                <mass>1</mass>
                <inertia>
                    <ixx>0.145833</ixx>
                    <ixy>0</ixy>
                    <ixz>0</ixz>
                    <iyy>0.145833</iyy>
                    <iyz>0</iyz>
                    <izz>0.125</izz>
                </inertia>
            </inertial>
            <visual name='visual'>
                <geometry>
                    <cylinder>
                        <radius>0.3</radius>
                        <length>0.1</length>
                    </cylinder>
                </geometry>
                <material>
                    <ambient>0.0 0.0 0.75 1</ambient>
                    <diffuse>0.0 0.0 0.75 1</diffuse>
                    <specular>0.0 0.0 0.75 1</specular>
                </material>
            </visual>
            <collision name='collision'>
                <geometry>
                    <cylinder>
                        <radius>0.3</radius>
                        <length>0.1</length>
                    </cylinder>
                </geometry>
            </collision>
        </link>

        <link name='caster'>
            <pose relative_to='chassis'>0.4 0 -0.1 0 0 0</pose>
            <inertial>
                <mass>1</mass>
                <inertia>
                    <ixx>0.1</ixx>
                    <ixy>0</ixy>
                    <ixz>0</ixz>
                    <iyy>0.1</iyy>
                    <iyz>0</iyz>
                    <izz>0.1</izz>
                </inertia>
            </inertial>

            <visual name='visual'>
                <geometry>
                    <sphere>
                        <radius>0.1</radius>
                    </sphere>
                </geometry>
                <material>
                    <ambient>0.0 0.0 0.75 1</ambient>
                    <diffuse>0.0 0.0 0.75 1</diffuse>
                    <specular>0.0 0.0 0.75 1</specular>
                </material>
            </visual>

            <collision name='collision'>
                <geometry>
                    <sphere>
                        <radius>0.1</radius>
                    </sphere>
                </geometry>
            </collision>
        </link>

        <!--connecting these links together using joints-->
        <joint name='left_wheel_joint' type='revolute'> <!--continous joint is not supported yet-->
            <pose relative_to='left_wheel'/>
            <parent>chassis</parent>
            <child>left_wheel</child>
            <axis>
                <xyz expressed_in='__model__'>0 1 0</xyz> <!--can be descired to any frame or even arbitrary frames-->
                <limit>
                    <lower>-1.79769e+308</lower>    <!--negative infinity-->
                    <upper>1.79769e+308</upper>     <!--positive infinity-->
                </limit>
            </axis>
        </joint>

        <joint name='right_wheel_joint' type='revolute'>
            <pose relative_to='right_wheel'/>
            <parent>chassis</parent>
            <child>right_wheel</child>
            <axis>
                <xyz expressed_in='__model__'>0 1 0</xyz>
                <limit>
                    <lower>-1.79769e+308</lower>    <!--negative infinity-->
                    <upper>1.79769e+308</upper>     <!--positive infinity-->
                </limit>
            </axis>
        </joint>

        <!--different type of joints ball joint--> <!--defult value is the child-->
        <joint name='caster_wheel' type='ball'>
            <parent>chassis</parent>
            <child>caster</child>
        </joint>



        <link name="hokuyo_link">
            <pose relative_to="chassis">0.3 0 0.15 0 0 0</pose>
            <inertial>
                <mass>1e-5</mass>
                <inertia>
                    <ixx>1e-6</ixx>
                    <ixy>0</ixy>
                    <ixz>0</ixz>
                    <iyy>1e-6</iyy>
                    <iyz>0</iyz>
                    <izz>1e-6</izz>
                </inertia>
            </inertial>

            <visual name='visual'>
                <geometry>
                    <box>
                        <size>0.05 0.05 0.05</size>
                    </box>
                </geometry>
                <material>
                    <ambient>1 0 0 1</ambient>
                    <diffuse>1 0 0 1</diffuse>
                    <specular>1 0 0 1</specular>
                </material>
            </visual>

            <collision name='collision'>
                <geometry>
                    <box>
                        <size>0.1 0.1 0.1</size>
                    </box>
                </geometry>
            </collision>

            <sensor type="gpu_ray" name="head_hokuyo_sensor">
                <pose>0 0 0 0 0 0</pose>
                <visualize>true</visualize>
                <update_rate>40</update_rate>
                <ray>
                    <scan>
                        <horizontal>
                            <samples>720</samples>
                            <resolution>1</resolution>
                            <min_angle>-1.570796</min_angle>
                            <max_angle>1.570796</max_angle>
                        </horizontal>
                    </scan>

                    <range>
                        <min>0.10</min>
                        <max>30.0</max>
                        <resolution>0.01</resolution>
                    </range>

                    <noise>
                        <type>gaussian</type>
                        <mean>0.0</mean>
                        <stddev>0.01</stddev>
                    </noise>
                </ray>
            </sensor>

            <plugin name="gazebo_ros_head_hokuyo_controller" filename="libgazebo_ros_gpu_laser.so">
                <topicName>/sensors/laser/scan</topicName>
                <frameName>hokuyo_link</frameName>
            </plugin>
        </link>

        <joint name="hokuyo_joint" type="fixed">
            <pose relative_to='hokuyo_link'>0.15 0 0.1 0 0 0</pose>
            <parent>chassis</parent>
            <child>hokuyo_link</child>
            <axis>
                <xyz expressed_in='__model__'>0 1 0</xyz> 
                <limit>
                    <lower>-1.79769e+308</lower>
                    <upper>1.79769e+308</upper>   
                </limit>
            </axis>
        </joint>
    </model>   
</sdf>
